{"metadata": {"timestamp": "2024-04-17T23:07:56.045304+00:00", "tools": [{"externalReferences": [{"type": "build-system", "url": "https://github.com/CycloneDX/cyclonedx-python-lib/actions"}, {"type": "distribution", "url": "https://pypi.org/project/cyclonedx-python-lib/"}, {"type": "documentation", "url": "https://cyclonedx.github.io/cyclonedx-python-lib/"}, {"type": "issue-tracker", "url": "https://github.com/CycloneDX/cyclonedx-python-lib/issues"}, {"type": "license", "url": "https://github.com/CycloneDX/cyclonedx-python-lib/blob/main/LICENSE"}, {"type": "release-notes", "url": "https://github.com/CycloneDX/cyclonedx-python-lib/blob/main/CHANGELOG.md"}, {"type": "vcs", "url": "https://github.com/CycloneDX/cyclonedx-python-lib"}, {"type": "website", "url": "https://cyclonedx.org"}], "name": "cyclonedx-python-lib", "vendor": "CycloneDX", "version": "4.0.0"}, {"externalReferences": [{"type": "build-system", "url": "https://github.com/madpah/vexy/actions"}, {"type": "distribution", "url": "https://pypi.org/project/vexy/"}, {"type": "documentation", "url": "https://vexy.readthedocs.io/"}, {"type": "issue-tracker", "url": "https://github.com/madpah/vexy/issues"}, {"type": "license", "url": "https://github.com/madpah/vexy/blob/main/LICENSE"}, {"type": "release-notes", "url": "https://github.com/madpah/vexy/blob/main/CHANGELOG.md"}, {"type": "vcs", "url": "https://github.com/madpah/vexy"}], "name": "vexy", "vendor": "Vexy", "version": "0.3.1"}]}, "serialNumber": "urn:uuid:57d1d112-c29d-4e1e-b744-1d907e8b28fa", "version": 1, "vulnerabilities": [{"advisories": [{"url": "http://web.nvd.nist.gov/view/vuln/detail?vulnId=CVE-2023-50782"}, {"url": "https://github.com/advisories/GHSA-3ww4-gg4f-jr7f"}, {"url": "https://github.com/tomato42/marvin-toolkit/tree/master/example/pyca-cryptography"}], "affects": [{"ref": "urn:cdx:b6f6aa3d-d7bf-40fa-8de2-c40a941fd165/1#pkg:pypi/cryptography@41.0.7", "versions": [{"status": "unknown", "version": "41.0.7"}]}], "bom-ref": "3607dcd7-5b2f-4237-a76a-3a3a406b08e0", "cwes": [203], "description": "[CVE-2023-50782] CWE-203: Information Exposure Through Discrepancy", "detail": "A flaw was found in the python-cryptography package. This issue may allow a remote attacker to decrypt captured messages in TLS servers that use RSA key exchanges, which may lead to exposure of confidential or sensitive data.\n\nSonatype's research suggests that this CVE's details differ from those defined at NVD. See https://ossindex.sonatype.org/vulnerability/CVE-2023-50782 for details", "ratings": [{"method": "CVSSv3", "score": 7.5, "severity": "high", "source": {"name": "OSS Index by Sonatype", "url": "https://ossindex.sonatype.org/vulnerability/CVE-2023-50782?component-type=pypi&component-name=cryptography&utm_source=python-oss-index-lib%401.1.1&utm_medium=integration"}, "vector": "AV:N/AC:L/PR:N/UI:N/S:U/C:H/I:N/A:N"}], "references": [{"id": "CVE-2023-50782", "source": {"name": "OSS Index by Sonatype", "url": "https://ossindex.sonatype.org/vulnerability/CVE-2023-50782?component-type=pypi&component-name=cryptography&utm_source=python-oss-index-lib%401.1.1&utm_medium=integration"}}], "source": {"name": "OSS Index by Sonatype", "url": "https://ossindex.sonatype.org/"}}, {"advisories": [{"url": "http://web.nvd.nist.gov/view/vuln/detail?vulnId=CVE-2024-26130"}, {"url": "https://github.com/advisories/GHSA-6vqw-3v5j-54x4"}], "affects": [{"ref": "urn:cdx:b6f6aa3d-d7bf-40fa-8de2-c40a941fd165/1#pkg:pypi/cryptography@41.0.7", "versions": [{"status": "unknown", "version": "41.0.7"}]}], "bom-ref": "5ad292c8-90c5-4cae-b1aa-6a527df89d75", "cwes": [476], "description": "[CVE-2024-26130] CWE-476: NULL Pointer Dereference", "detail": "cryptography is a package designed to expose cryptographic primitives and recipes to Python developers. Starting in version 38.0.0 and prior to version 42.0.4, if `pkcs12.serialize_key_and_certificates` is called with both a certificate whose public key did not match the provided private key and an `encryption_algorithm` with `hmac_hash` set (via `PrivateFormat.PKCS12.encryption_builder().hmac_hash(...)`, then a NULL pointer dereference would occur, crashing the Python process. This has been resolved in version 42.0.4, the first version in which a `ValueError` is properly raised.\n\nSonatype's research suggests that this CVE's details differ from those defined at NVD. See https://ossindex.sonatype.org/vulnerability/CVE-2024-26130 for details", "ratings": [{"method": "CVSSv3", "score": 7.5, "severity": "high", "source": {"name": "OSS Index by Sonatype", "url": "https://ossindex.sonatype.org/vulnerability/CVE-2024-26130?component-type=pypi&component-name=cryptography&utm_source=python-oss-index-lib%401.1.1&utm_medium=integration"}, "vector": "AV:N/AC:L/PR:N/UI:N/S:U/C:N/I:N/A:H"}], "references": [{"id": "CVE-2024-26130", "source": {"name": "OSS Index by Sonatype", "url": "https://ossindex.sonatype.org/vulnerability/CVE-2024-26130?component-type=pypi&component-name=cryptography&utm_source=python-oss-index-lib%401.1.1&utm_medium=integration"}}], "source": {"name": "OSS Index by Sonatype", "url": "https://ossindex.sonatype.org/"}}], "$schema": "http://cyclonedx.org/schema/bom-1.4.schema.json", "bomFormat": "CycloneDX", "specVersion": "1.4"}